<?xml version='1.0'?>
<robot name="testrobot">

  <!-- Base Link -->
  <link name="base_link">
    <visual>
      <origin xyz="0 0 0" rpy="0 0 0" />
      <geometry>
          <mesh scale="0.001 0.001 0.001" filename="package://simulations/meshes/assem.stl"/>
      </geometry>
    </visual>
    <!-- Base collision, mass and inertia -->
    <collision>
      <origin xyz="0 0 0" rpy="0 0 0" />
      <geometry>
        <mesh scale="0.001 0.001 0.001" filename="package://simulations/meshes/assem.stl"/>
            
            
          
      </geometry>
    </collision>
    <inertial>
      <mass value="5"/>
      <inertia ixx="0.13" ixy="0.0" ixz="0.0" iyy="0.21" iyz="0.0" izz="0.13"/>
    </inertial>
    <!-- Caster -->
    <visual name="left_caster">
      <origin xyz="-0.008063 -0.272811 0.11980" rpy="1.570795 0 1.570795" />
      <geometry>
        <mesh scale="0.0254 0.0254 0.0254" filename="package://simulations/meshes/caster.stl"/>
      </geometry>
    </visual>
    <!-- Caster collision, mass and inertia -->
    <collision>
      <origin xyz="-0.008063 -0.272811 0.11980" rpy="1.570795 0 1.570795" />
      <geometry>
        <mesh scale="0.0254 0.0254 0.0254" filename="package://simulations/meshes/caster.stl"/>
      </geometry>
    </collision>
    <inertial>
      <mass value="0.5"/>
      <inertia ixx="0.0001" ixy="0.0" ixz="0.0" iyy="0.0001" iyz="0.0" izz="0.0001"/>
    </inertial>
        <!-- Caster -->
    <visual name="right_caster">
      <origin xyz="-0.297163 -0.274811 0.11980" rpy="1.570795 0 1.570795" />
      <geometry>
        <mesh scale="0.0254 0.0254 0.0254" filename="package://simulations/meshes/caster.stl"/>
      </geometry>
    </visual>
    <!-- Caster collision, mass and inertia -->
    <collision>
      <origin xyz="-0.297163 -0.274811 0.11980" rpy="1.570795 0 1.570795" />
      <geometry>
        <mesh scale="0.0254 0.0254 0.0254" filename="package://simulations/meshes/caster.stl"/>
      </geometry>
    </collision>
    <inertial>
      <mass value="0.5"/>
      <inertia ixx="0.0001" ixy="0.0" ixz="0.0" iyy="0.0001" iyz="0.0" izz="0.0001"/>
    </inertial>
        <!-- Caster -->
    <visual name="right_motor_frame">
      <origin xyz="-0.290813 0.124882 0.04440" rpy="0 0 1.570795" />
      <geometry>
        <mesh scale="0.001 0.001 0.001" filename="package://simulations/meshes/motorframe.stl"/>
      </geometry>
    </visual>
    <!-- Caster collision, mass and inertia -->
    <collision>
      <origin xyz="-0.290813 0.124882 0.04440" rpy="0 0 1.570795" />
      <geometry>
        <mesh scale="0.001 0.001 0.001" filename="package://simulations/meshes/motorframe.stl"/>
      </geometry>
    </collision>
    <inertial>
      <mass value="0.5"/>
      <inertia ixx="0.0001" ixy="0.0" ixz="0.0" iyy="0.0001" iyz="0.0" izz="0.0001"/>
    </inertial>
        <!-- Caster -->
    <visual name="right_k_motor">
      <origin xyz="-0.387513 0.183529 0.122523" rpy="1.570795 1.570795  0" />
      <geometry>
        <mesh scale="0.001 0.001 0.001" filename="package://simulations/meshes/kmotor.stl"/>
      </geometry>
    </visual>
    <!-- Caster collision, mass and inertia -->
    <collision>
      <origin xyz="-0.387513 0.183529 0.122523" rpy="1.570795 1.570795 0 " />
      <geometry>
        <mesh scale="0.001 0.001 0.001" filename="package://simulations/meshes/kmotor.stl"/>
      </geometry>
    </collision>
    <inertial>
      <mass value="0.5"/>
      <inertia ixx="0.0001" ixy="0.0" ixz="0.0" iyy="0.0001" iyz="0.0" izz="0.0001"/>
    </inertial>

        <!-- Caster -->
    <visual name="left_motor_frame">
      <origin xyz="-0.011413 0.242164 0.04440" rpy="0 0 -1.570795" />
      <geometry>
        <mesh scale="0.001 0.001 0.001" filename="package://simulations/meshes/motorframe.stl"/>
      </geometry>
    </visual>
    <!-- Caster collision, mass and inertia -->
    <collision>
      <origin xyz="-0.011413 0.242164 0.04440" rpy="0 0 -1.570795" />
      <geometry>
        <mesh scale="0.001 0.001 0.001" filename="package://simulations/meshes/motorframe.stl"/>
      </geometry>
    </collision>
    <inertial>
      <mass value="0.5"/>
      <inertia ixx="0.0001" ixy="0.0" ixz="0.0" iyy="0.0001" iyz="0.0" izz="0.0001"/>
    </inertial>
        <!-- Caster -->
    <visual name="left_k_motor">
      <origin xyz="0.085287 0.183517 0.122477" rpy="1.570795 -1.570795  0" />
      <geometry>
        <mesh scale="0.001 0.001 0.001" filename="package://simulations/meshes/kmotor.stl"/>
      </geometry>
    </visual>
    <!-- Caster collision, mass and inertia -->
    <collision>
      <origin xyz="0.085287 0.183517 0.122477" rpy="1.570795 -1.570795 0" />
      <geometry>
        <mesh scale="0.001 0.001 0.001" filename="package://simulations/meshes/kmotor.stl"/>
      </geometry>
    </collision>
    <inertial>
      <mass value="0.5"/>
      <inertia ixx="0.0001" ixy="0.0" ixz="0.0" iyy="0.0001" iyz="0.0" izz="0.0001"/>
    </inertial>


   
  </link>

  <gazebo reference="base_link">
    <material>Gazebo/Blue</material>
    <pose>0 0 3 0 0 0</pose>
  </gazebo>

  <!-- Right Wheel -->
  <link name="right_wheel">
    <visual>
      <origin xyz="0 0 0" rpy="0 -1.570795 0" />
      <geometry>
        <mesh scale="0.001 0.001 0.001" filename="package://simulations/meshes/jwheel.stl"/>
      </geometry>
    </visual>
    <!-- Left Wheel collision, mass and inertia -->
    <collision>
      <origin xyz="0 0 0" rpy="0 -1.570795 0" />
      <geometry>
        <mesh scale="0.001 0.001 0.001" filename="package://simulations/meshes/jwheel.stl"/>
      </geometry>
    </collision>
    <inertial>
      <mass value="0.5"/>
      <inertia ixx="0.01" ixy="0.0" ixz="0.0" iyy="0.005" iyz="0.0" izz="0.005"/>
    </inertial>

  </link>

  <gazebo reference="right_wheel">
    <material>Gazebo/Black</material>
  </gazebo>

  <!-- Right Wheel joint -->
  <joint name="joint_right_wheel" type="continuous">
    <parent link="base_link"/>
    <child link="right_wheel"/>
    <origin xyz="-0.360523 0.183529 0.1222523" rpy="0 0 0" /> 
    <axis xyz="1 0 0"/>
  </joint>

  <!-- Left Wheel -->
  <link name="left_wheel">
    <visual>
      <origin xyz="0 0 0" rpy="0 1.570795 0" />
      <geometry>
        <mesh scale="0.001 0.001 0.001" filename="package://simulations/meshes/jwheel.stl"/>
      </geometry>
    </visual>
    <!-- Left Wheel collision, mass and inertia -->
    <collision>
      <origin xyz="0 0 0" rpy="0 1.570795 0" />
      <geometry>
        <mesh scale="0.001 0.001 0.001" filename="package://simulations/meshes/jwheel.stl"/>
      </geometry>
    </collision>
    <inertial>
      <mass value="0.5"/>
      <inertia ixx="0.01" ixy="0.0" ixz="0.0" iyy="0.005" iyz="0.0" izz="0.005"/>
    </inertial>

  </link>
    <gazebo reference="left_wheel">
    <material>Gazebo/Black</material>
  </gazebo>

  <!-- Right Wheel joint -->
  <joint name="joint_left_wheel" type="continuous">
    <parent link="base_link"/>
    <child link="left_wheel"/>
    <origin xyz="0.058297 0.183517 0.122477" rpy="0 0 0" /> 
    <axis xyz="1 0 0"/>
  </joint>
  <gazebo>
    <plugin name="differential_drive_controller" filename="libgazebo_ros_diff_drive.so">
      <legacyMode>false</legacyMode>
      <alwaysOn>true</alwaysOn>
      <updateRate>20</updateRate>
      <leftJoint>joint_left_wheel</leftJoint>
      <rightJoint>joint_right_wheel</rightJoint>
      <wheelSeparation>0.4</wheelSeparation>
      <wheelDiameter>0.1</wheelDiameter>
      <torque>20</torque>
      <commandTopic>cmd_vel</commandTopic>
      <odometryTopic>odom</odometryTopic>
      <odometryFrame>odom</odometryFrame>
      <robotBaseFrame>chassis</robotBaseFrame>
    </plugin>
  </gazebo>








</robot>
